Reading data
============

Generating graphs
=================

andre_50
---------

2 objectives
3 objectives
5 objectives
andre_300
---------

2 objectives
3 objectives
5 objectives
andre_1000
---------

2 objectives
3 objectives
5 objectives
real
---------

2 objectives
3 objectives
5 objectives
Reading data
============

Comparing GA with NSGA-II using two objetives
=============================================

andre_50
---------

('ga', 'andre_50', None)
Traceback (most recent call last):
  File "004_plot_pareto_front.py", line 139, in <module>
    scatter.save(filepath)
  File "/home/joaovitor/.local/lib/python3.6/site-packages/pymoo/core/plot.py", line 184, in save
    self.fig.savefig(fname, **kwargs)
  File "/usr/local/lib/python3.6/dist-packages/matplotlib/figure.py", line 2311, in savefig
    self.canvas.print_figure(fname, **kwargs)
  File "/usr/local/lib/python3.6/dist-packages/matplotlib/backend_bases.py", line 2217, in print_figure
    **kwargs)
  File "/usr/local/lib/python3.6/dist-packages/matplotlib/backend_bases.py", line 1639, in wrapper
    return func(*args, **kwargs)
  File "/usr/local/lib/python3.6/dist-packages/matplotlib/backends/backend_agg.py", line 512, in print_png
    dpi=self.figure.dpi, metadata=metadata, pil_kwargs=pil_kwargs)
  File "/usr/local/lib/python3.6/dist-packages/matplotlib/image.py", line 1611, in imsave
    image.save(fname, **pil_kwargs)
  File "/usr/local/lib/python3.6/dist-packages/PIL/Image.py", line 2237, in save
    fp = builtins.open(filename, "w+b")
FileNotFoundError: [Errno 2] No such file or directory: 'results/frente_pareto/andre_50/2 objectives/ga/0.png'
Reading data
============

Comparing GA with NSGA-II using two objetives
=============================================

andre_50
---------

('ga', 'andre_50', None)
('nsga_ii', 'andre_50', 2)
Traceback (most recent call last):
  File "004_plot_pareto_front.py", line 139, in <module>
    scatter.save(filepath)
  File "/home/joaovitor/.local/lib/python3.6/site-packages/pymoo/core/plot.py", line 184, in save
    self.fig.savefig(fname, **kwargs)
  File "/usr/local/lib/python3.6/dist-packages/matplotlib/figure.py", line 2311, in savefig
    self.canvas.print_figure(fname, **kwargs)
  File "/usr/local/lib/python3.6/dist-packages/matplotlib/backend_bases.py", line 2217, in print_figure
    **kwargs)
  File "/usr/local/lib/python3.6/dist-packages/matplotlib/backend_bases.py", line 1639, in wrapper
    return func(*args, **kwargs)
  File "/usr/local/lib/python3.6/dist-packages/matplotlib/backends/backend_agg.py", line 512, in print_png
    dpi=self.figure.dpi, metadata=metadata, pil_kwargs=pil_kwargs)
  File "/usr/local/lib/python3.6/dist-packages/matplotlib/image.py", line 1611, in imsave
    image.save(fname, **pil_kwargs)
  File "/usr/local/lib/python3.6/dist-packages/PIL/Image.py", line 2237, in save
    fp = builtins.open(filename, "w+b")
FileNotFoundError: [Errno 2] No such file or directory: 'results/frente_pareto/andre_50/2 objectives/nsga_ii_2/0.png'
Reading data
============

Comparing GA with NSGA-II using two objetives
=============================================

andre_50
---------

('ga', 'andre_50', None)
('nsga_ii', 'andre_50', 2)
('nsga_ii', 'andre_50', 3)
Traceback (most recent call last):
  File "004_plot_pareto_front.py", line 120, in <module>
    best_population = get_results_best_n_objectives(results, 2)
  File "/home/joaovitor/projetoACS/evolutionary-ACS-benchmark/read/algorithm.py", line 141, in get_results_best_n_objectives
    population[i, j, k] = multi_fitness(results_selected[i, j, k], results_instance, j, timer)
ValueError: cannot copy sequence with size 5 to array axis with dimension 2
Traceback (most recent call last):
  File "004_plot_pareto_front.py", line 10, in <module>
    from pymoo.indicators.hv import HV
ImportError: cannot import name 'HV'
Traceback (most recent call last):
  File "004_plot_pareto_front.py", line 10, in <module>
    from pymoo.indicators.hv import HV
ImportError: cannot import name 'HV'
Traceback (most recent call last):
  File "004_plot_pareto_front.py", line 10, in <module>
    from pymoo.indicators.hv import HV
ImportError: cannot import name 'HV'
Traceback (most recent call last):
  File "004_plot_pareto_front.py", line 10, in <module>
    from pymoo.performance_indicator.hv import Hypervolume
ModuleNotFoundError: No module named 'pymoo.performance_indicator'
Reading data
============

Generating metrics
=================

andre_50
---------

2 objectives
Traceback (most recent call last):
  File "004_plot_pareto_front.py", line 130, in <module>
    hv_value = hv.do(problem_best_population)
  File "/home/joaovitor/.local/lib/python3.6/site-packages/pymoo/core/indicator.py", line 27, in do
    return self._do(F, *args, **kwargs)
  File "/home/joaovitor/.local/lib/python3.6/site-packages/pymoo/indicators/hv.py", line 86, in _do
    val = hv.compute(F)
  File "/home/joaovitor/.local/lib/python3.6/site-packages/pymoo/vendor/hv.py", line 56, in compute
    if weaklyDominates(point, referencePoint):
  File "/home/joaovitor/.local/lib/python3.6/site-packages/pymoo/vendor/hv.py", line 47, in weaklyDominates
    if point[i] > other[i]:
KeyError: 0
Reading data
============

Generating metrics
=================

andre_50
---------

2 objectives
Traceback (most recent call last):
  File "004_plot_pareto_front.py", line 130, in <module>
    hv_value = hv.do(problem_best_population)
  File "/home/joaovitor/.local/lib/python3.6/site-packages/pymoo/core/indicator.py", line 27, in do
    return self._do(F, *args, **kwargs)
  File "/home/joaovitor/.local/lib/python3.6/site-packages/pymoo/indicators/hv.py", line 86, in _do
    val = hv.compute(F)
  File "/home/joaovitor/.local/lib/python3.6/site-packages/pymoo/vendor/hv.py", line 56, in compute
    if weaklyDominates(point, referencePoint):
  File "/home/joaovitor/.local/lib/python3.6/site-packages/pymoo/vendor/hv.py", line 47, in weaklyDominates
    if point[i] > other[i]:
KeyError: 0
